Workbook

Sheet 图表
A1: 交投矿业爆破成本分析报告 ｜ Blasting Cost Analytics
A2: 汇报期间：2025年–2026年 · 数据截至：2026年8月 · 空白月份为预留区间（数据产生后图表自动更新）
A43: 图表1 数据源（宕渣/骨料均价，元/吨；无数据显示 #N/A 断开）
D44: 1月 | E44: 2-3月 | F44: 4-5月 | G44: 6月 | H44: 7月 | I44: 8月 | J44: 9月 | K44: 10月 | L44: 11月 | M44: 12月
A45: 2025年宕渣 | D45: =IF(ISNUMBER('核心指标-开采比例'!D23),'核心指标-开采比例'!D23,NA()) -> 7.8494469 | E45: =IF(ISNUMBER('核心指标-开采比例'!E23),'核心指标-开采比例'!E23,NA()) -> 7.6200132 | F45: =IF(ISNUMBER('核心指标-开采比例'!F23),'核心指标-开采比例'!F23,NA()) -> 7.2896785 | G45: =IF(ISNUMBER('核心指标-开采比例'!G23),'核心指标-开采比例'!G23,NA()) -> 7.432341 | H45: =IF(ISNUMBER('核心指标-开采比例'!H23),'核心指标-开采比例'!H23,NA()) -> 7.1233174 | I45: =IF(ISNUMBER('核心指标-开采比例'!I23),'核心指标-开采比例'!I23,NA()) -> #N/A | J45: =IF(ISNUMBER('核心指标-开采比例'!J23),'核心指标-开采比例'!J23,NA()) -> #N/A | K45: =IF(ISNUMBER('核心指标-开采比例'!K23),'核心指标-开采比例'!K23,NA()) -> #N/A | ... M45: =IF(ISNUMBER('核心指标-开采比例'!M23),'核心指标-开采比例'!M23,NA()) -> #N/A
A46: 2026年宕渣 | D46: =IF(ISNUMBER('核心指标-开采比例'!D10),'核心指标-开采比例'!D10,NA()) -> 8.5796332 | E46: =IF(ISNUMBER('核心指标-开采比例'!E10),'核心指标-开采比例'!E10,NA()) -> 6.2175691 | F46: =IF(ISNUMBER('核心指标-开采比例'!F10),'核心指标-开采比例'!F10,NA()) -> 8.5003011 | G46: =IF(ISNUMBER('核心指标-开采比例'!G10),'核心指标-开采比例'!G10,NA()) -> 8.0095488 | H46: =IF(ISNUMBER('核心指标-开采比例'!H10),'核心指标-开采比例'!H10,NA()) -> 8.6939962 | I46: =IF(ISNUMBER('核心指标-开采比例'!I10),'核心指标-开采比例'!I10,NA()) -> 7.8840545 | J46: =IF(ISNUMBER('核心指标-开采比例'!J10),'核心指标-开采比例'!J10,NA()) -> #N/A | K46: =IF(ISNUMBER('核心指标-开采比例'!K10),'核心指标-开采比例'!K10,NA()) -> #N/A | ... M46: =IF(ISNUMBER('核心指标-开采比例'!M10),'核心指标-开采比例'!M10,NA()) -> #N/A
A47: 2025年骨料 | D47: =IF(ISNUMBER('核心指标-开采比例'!D27),'核心指标-开采比例'!D27,NA()) -> 6.76 | E47: =IF(ISNUMBER('核心指标-开采比例'!E27),'核心指标-开采比例'!E27,NA()) -> 6.76 | F47: =IF(ISNUMBER('核心指标-开采比例'!F27),'核心指标-开采比例'!F27,NA()) -> 6.7671573 | G47: =IF(ISNUMBER('核心指标-开采比例'!G27),'核心指标-开采比例'!G27,NA()) -> 6.9299227 | H47: =IF(ISNUMBER('核心指标-开采比例'!H27),'核心指标-开采比例'!H27,NA()) -> 6.9729342 | I47: =IF(ISNUMBER('核心指标-开采比例'!I27),'核心指标-开采比例'!I27,NA()) -> 6.8519658 | J47: =IF(ISNUMBER('核心指标-开采比例'!J27),'核心指标-开采比例'!J27,NA()) -> 6.8848242 | K47: =IF(ISNUMBER('核心指标-开采比例'!K27),'核心指标-开采比例'!K27,NA()) -> 6.850472 | ... M47: =IF(ISNUMBER('核心指标-开采比例'!M27),'核心指标-开采比例'!M27,NA()) -> 6.8906953
A48: 2026年骨料 | D48: =IF(ISNUMBER('核心指标-开采比例'!D14),'核心指标-开采比例'!D14,NA()) -> 6.8564946 | E48: =IF(ISNUMBER('核心指标-开采比例'!E14),'核心指标-开采比例'!E14,NA()) -> 6.844386 | F48: =IF(ISNUMBER('核心指标-开采比例'!F14),'核心指标-开采比例'!F14,NA()) -> 6.9388506 | G48: =IF(ISNUMBER('核心指标-开采比例'!G14),'核心指标-开采比例'!G14,NA()) -> 7.0568426 | H48: =IF(ISNUMBER('核心指标-开采比例'!H14),'核心指标-开采比例'!H14,NA()) -> 7.1055723 | I48: =IF(ISNUMBER('核心指标-开采比例'!I14),'核心指标-开采比例'!I14,NA()) -> 7.060367 | J48: =IF(ISNUMBER('核心指标-开采比例'!J14),'核心指标-开采比例'!J14,NA()) -> #N/A | K48: =IF(ISNUMBER('核心指标-开采比例'!K14),'核心指标-开采比例'!K14,NA()) -> #N/A | ... M48: =IF(ISNUMBER('核心指标-开采比例'!M14),'核心指标-开采比例'!M14,NA()) -> #N/A
A50: 图表2 数据源（开采比例，%）
A51: 年份/矿种 | B51: 表土剥离 | C51: 爆破开采 | D51: 机械开采
A52: 2026年骨料 | C52: ='核心指标-开采比例'!O11 -> 0.95429601 | D52: ='核心指标-开采比例'!O12 -> 0.045703986
A53: 2025年骨料 | C53: ='核心指标-开采比例'!O24 -> 0.97839495 | D53: ='核心指标-开采比例'!O25 -> 0.021605052
A54: 2026年宕渣 | B54: ='核心指标-开采比例'!O6 -> 0.25491108 | C54: ='核心指标-开采比例'!O7 -> 0.55871432 | D54: ='核心指标-开采比例'!O8 -> 0.1863746
A55: 2025年宕渣 | B55: ='核心指标-开采比例'!O19 -> 0.23724219 | C55: ='核心指标-开采比例'!O20 -> 0.75297105 | D55: ='核心指标-开采比例'!O21 -> 0.0097867616
A57: ="26年骨料平均开采成本："&TEXT('核心指标-开采比例'!N14,"0.00")&" 元/吨"&CHAR(10)&"25年骨料平均开采成本："&TEXT('核心指标-开采比例'!N27,"0.00")&" 元/吨"&CHAR(10)&"26年宕渣开采成本："&TEXT('核心指标-开采比例'!N10,"0.00")&" 元/吨"&CHAR(10)&"25年宕渣开采成本："&TEXT('核心指标-开采比例'!N23,"0.00")&" 元/吨" -> 26年骨料平均开采成本：6.95 元/吨 25年骨料平均开采成本：6.85 元/吨 26年宕渣开采成本：7.95 元/吨 25年宕渣开采成本：7.30 元/吨

Sheet 基础资料-生产资料
A2: 2026年度生产数据（调整版）
O4: 单位：吨
A5: 项目 | E5: 1月 | F5: 2月 | G5: 3月 | H5: 4月 | I5: 5月 | J5: 6月 | K5: 7月 | L5: 8月 | M5: 9月 | N5: 10月 | O5: 11月 | P5: 12月 | Q5: 合计
A6: 开采量 | B6: 大皇山 | C6: 宕渣 | E6: 189082.9 | F6: 32925.05 | G6: 79963.73 | H6: 90578.25 | I6: 68277.5 | J6: 308815.3 | K6: 32072.1 | L6: 111991.7 | Q6: =SUM(E6:P6) -> 913706.53
C7: 土方 | E7: 427130.5 | F7: 122428.3 | G7: 277243.75 | H7: 420235.96 | I7: 257420.65 | J7: 0 | K7: 0 | L7: 0 | Q7: =SUM(E7:P7) -> 1504459.2
C8: 老线 | D8: 破碎量： | E8: 1332094.2 | F8: 669731.4 | G8: 724342.1 | H8: 1274223.2 | I8: 973700.5 | J8: 1185003.6 | K8: 597014.55 | L8: 1021527.2 | Q8: =SUM(E8:P8) -> 7777636.9
C9: 新线 | D9: 破碎量： | E9: 526684.49 | F9: 241147.94 | G9: 282280.77 | H9: 480767.83 | I9: 373518.09 | J9: 599144.12 | K9: 164263.62 | L9: 0 | Q9: =SUM(E9:P9) -> 2667806.9
A12: 2025年度生产数据（调整版）
O14: 单位：吨
A15: 项目 | E15: 1月 | F15: 2月 | G15: 3月 | H15: 4月 | I15: 5月 | J15: 6月 | K15: 7月 | L15: 8月 | M15: 9月 | N15: 10月 | O15: 11月 | P15: 12月 | Q15: 合计
A16: 开采量 | B16: 大皇山 | C16: 宕渣 | E16: 0 | F16: 0 | G16: 0 | H16: 0 | I16: 0 | J16: 19808.4 | K16: 0 | L16: 0 | M16: 0 | N16: 0 | O16: 0 | P16: 0 | Q16: =SUM(E16:P16) -> 19808.4
C17: 土方 | E17: 302452.34 | F17: 268007.6 | G17: 394472.15 | H17: 494860.65 | I17: 303153.05 | J17: 385535.1 | K17: 400373.65 | L17: 42465.6 | M17: 0 | N17: 0 | O17: 0 | P17: 0 | Q17: =SUM(E17:P17) -> 2591320.1
C18: 老线 | D18: 破碎量： | E18: 620265.55 | F18: 451278.7 | G18: 814257.5 | H18: 1120405 | I18: 1461011.8 | J18: 1447575.1 | K18: 1432463.2 | L18: 1314101.5 | M18: 1452347.9 | N18: 1206269.9 | O18: 1326113.1 | P18: 1435938.1 | Q18: =SUM(E18:P18) -> 14082027 | R18: =Q18+Q19-E18-E19 -> 19374555
C19: 新线 | D19: 破碎量： | E19: =169547.98+1028.89 -> 170576.87 | F19: 146213.5 | G19: 320603.03 | H19: 501154.67 | I19: 667030.08 | J19: 618556.08 | K19: 594737.02 | L19: 608701.43 | M19: 686250.66 | N19: 520960.97 | O19: 641610 | P19: 606976.01 | Q19: =SUM(E19:P19) -> 6083370.3
F22: =F17+G17 -> 662479.75
E23: =E18+E19 -> 790842.42
E26: 306655.89 | F26: 1 | G26: 23 | H26: 45 | I26: 6 | J26: 7
E27: = | F27: 306655.89 | G27: 671849.7 | H27: 828173.95 | I27: 415133.2 | J27: 400418.3
F28: =E17 -> 302452.34 | G28: =F17+G17 -> 662479.75 | H28: =H17+I17 -> 798013.7 | I28: =J16+J17 -> 405343.5 | J28: =K17 -> 400373.65

Sheet 基础资料-结算资料
A3: 项目 | C3: 11期 | F3: 12期 | I3: 13期 | L3: 14期 | O3: 15期（暂结） | R3: 16期（暂结）
C4: 1月 | F4: 2-3月 | I4: 4-5月 | L4: 6月 | O4: 7月 | R4: 8月
C5: 数量 | D5: 单价 | E5: 金额 | F5: 数量 | G5: 单价 | H5: 金额 | I5: 数量 | J5: 单价 | K5: 金额 | L5: 数量 | M5: 单价 | N5: 金额 | O5: 数量 | P5: 单价 | Q5: 金额 | R5: 数量 | S5: 单价 | T5: 金额
A6: 100章总则 | B6: 一、安全生产费 | F6: 398716.81 | G6: 1 | H6: 398716.81 | I6: 659339.2 | J6: 1 | K6: 659339.2 | O6: 311034.8 | P6: 1 | Q6: 311034.8 | R6: 169129.2 | S6: 1 | T6: 169129.2
B7: 二、其他 | E7: 0 | H7: 0 | K7: 0 | N7: 0
B8: 小计 | E8: =E6+E7 -> 0 | H8: =H6+H7 -> 398716.81 | K8: =K6+K7 -> 659339.2 | N8: =N6+N7 -> 0 | Q8: =Q6+Q7 -> 311034.8 | T8: =T6+T7 -> 169129.2
A9: 200章矿山开拓工程 | B9: 一、爆破开采 | E9: =E10+E11 -> 14002639 | H9: =H10+H11 -> 13594925 | K9: =K10+K11 -> 24629504 | N9: =N10+N11 -> 13934943 | Q9: =Q10+Q11 -> 4929116.6 | T9: =T10+T11 -> 7236823.3
B10: 1、码头（土方、宕渣） | C10: 217005.54 | D10: 7.96 | E10: 1727364.1 | F10: 112348.5 | G10: 7.96 | H10: 894294.06 | I10: 572343.61 | J10: 7.96 | K10: 4555855.1 | L10: 343040.8 | M10: 7.96 | N10: 2730604.8 | O10: 26172.15 | P10: 7.96 | Q10: =O10*P10 -> 208330.31 | R10: 103959.45 | S10: 7.96 | T10: =R10*S10 -> 827517.22
B11: 2、卸料口（骨料） | C11: 1815869.1 | D11: 6.76 | E11: 12275275 | F11: 1878791.6 | G11: 6.76 | H11: 12700631 | I11: 2969474.7 | J11: 6.76 | K11: 20073649 | L11: 1657446.6 | M11: 6.76 | N11: 11204339 | O11: 698341.17 | P11: 6.76 | Q11: =O11*P11 -> 4720786.3 | R11: 948122.2 | S11: 6.76 | T11: =R11*S11 -> 6409306.1
B12: 机械开采 | C12: =C13+C14 -> 267899.1 | E12: =E13+E14 -> 3160305.4 | F12: =F13+F14 -> 80656.88 | H12: =H13+H14 -> 925171.47 | I12: =I13+I14 -> 310275.68 | K12: =K13+K14 -> 3575507.5 | L12: =L13+L14 -> 132753.52 | N12: =N13+N14 -> 1458496.9 | Q12: =Q13+Q14 -> 759094.18 | T12: =T13+T14 -> 829329.16
B13: 1、码头（土方、宕渣） | C13: 224989.5 | D13: 11.96 | E13: 2690874.4 | F13: 41946.28 | G13: 11.96 | H13: 501677.51 | I13: 177540.73 | J13: 11.96 | K13: 2123387.1 | L13: 6052.3 | M13: 11.96 | N13: 72385.51 | O13: 5899.95 | P13: 11.96 | Q13: =O13*P13 -> 70563.402 | R13: 2197.15 | S13: 11.96 | T13: =R13*S13 -> 26277.914
B14: 2、卸料口（骨料） | C14: 42909.6 | D14: 10.94 | E14: 469431.02 | F14: 38710.6 | G14: 10.94 | H14: 423493.96 | I14: 132734.95 | J14: 10.94 | K14: 1452120.4 | L14: 126701.22 | M14: 10.94 | N14: 1386111.4 | O14: 62937 | P14: 10.94 | Q14: =O14*P14 -> 688530.78 | R14: 73405.05 | S14: 10.94 | T14: =R14*S14 -> 803051.25
B15: 三、剥离表土运输 | C15: 174272.96 | D15: 5 | E15: 871364.8 | F15: 358266.05 | G15: 5 | H15: 1791330.2 | I15: 86628.02 | J15: 5 | K15: 433140.1 | L15: 2276.6 | M15: 5 | N15: 11383 | R15: 5835.1 | S15: 5 | T15: =R15*S15 -> 29175.5
B16: 四、200章其他 | E16: 0 | H16: 48313.29 | K16: 0 | N16: 266314.49
B17: 小计 | E17: =E9+E12+E15+E16 -> 18034310 | H17: =H9+H12+H15+H16 -> 16359740 | K17: =K9+K12+K15+K16 -> 28638151 | N17: =N9+N12+N15+N16 -> 15671138 | O17: =O9+O12+O15+O16 -> 0 | P17: =P9+P12+P15+P16 -> 0 | Q17: =Q9+Q12+Q15+Q16 -> 5688210.8 | R17: =R9+R12+R15+R16 -> 5835.1 | S17: =S9+S12+S15+S16 -> 5 | T17: =T9+T12+T15+T16 -> 8095328
A18: 300章生产线工程 | E18: 0 | H18: 0 | K18: 908631.88 | N18: 144251.52 | Q18: 804107.72 | T18: 31021.16
A19: 暂列金（租费+油费） | E19: 221118.33 | H19: 265859.25 | K19: 338159.92 | N19: 218521.45 | Q19: =218341.42+448293.63 -> 666635.05 | T19: 133782.19
A20: 计量合计 | E20: =E8+E17+E18+E19 -> 18255428 | H20: =H8+H17+H18+H19 -> 17024316 | K20: =K8+K17+K18+K19 -> 30544282 | N20: =N8+N17+N18+N19 -> 16033911 | Q20: =Q8+Q17+Q18+Q19 -> 7469988.4 | T20: =T8+T17+T18+T19 -> 8429260.5
A21: 当期扣款 | B21: 柴油调差款 | E21: -224903.58 | H21: -224903.58 | K21: 0 | N21: 0 | Q21: 0
B22: 扣炸药库及储油站使用费 | E22: -4000000 | H22: -4000000 | K22: 0 | N22: 0 | Q22: 0
B23: 综合保障基地租金 | E23: -327690.57 | H23: -327690.57 | K23: 0 | N23: 0 | Q23: 0
B24: 38号带修理材料费用 | E24: -84930.37 | H24: -84930.37 | K24: 0 | N24: 0 | Q24: 0
B25: 扣水电使用费 | E25: -194126.4 | H25: -194126.4 | K25: -216819.4 | N25: -651253.9 | Q25: -320895.8
B26: 机制砂费用 | E26: 0 | H26: 0 | K26: 0 | N26: -39417.93 | Q26: 0
B27: 保留金 | E27: -1342377.7 | H27: -1342377.7 | K27: -1680749.7 | N27: -3076224.3 | Q27: -1585726.6
A37: 项目 | C37: 60期(扣除前期差额） | F37: 01期 | I37: 02期 | L37: 03期 | O37: 4期 | R37: 5期 | U37: 6期 | X37: 7期 | AA37: 8期 | AD37: 9期 | AG37: 10期
C38: 1月 | F38: 2-3月 | I38: 4月 | L38: 5月 | O38: 6月 | R38: 7月 | U38: 8月 | X38: 9月 | AA38: 10月 | AD38: 11月 | AG38: 12月
C39: 数量 | D39: 单价 | E39: 金额 | F39: 数量 | G39: 单价 | H39: 金额 | I39: 数量 | J39: 单价 | K39: 金额 | L39: 数量 | M39: 单价 | N39: 金额 | O39: 数量 | P39: 单价 | Q39: 金额 | R39: 数量 | S39: 单价 | T39: 金额 | U39: 数量 | V39: 单价 | W39: 金额 | X39: 数量 | Y39: 单价 | Z39: 金额 | AA39: 数量 | AB39: 单价 | AC39: 金额 | AD39: 数量 | AE39: 单价 | AF39: 金额 | AG39: 数量 | AH39: 单价 | AI39: 金额
A40: 100章总则 | B40: 一、安全生产费 | C40: 603000 | D40: 1 | E40: 603000 | F40: 1478255.8 | G40: 1 | H40: 1478255.8 | U40: 811226.18 | V40: 1 | W40: 811226.18 | X40: 41805 | Y40: 1 | Z40: 41805 | AA40: 165062 | AB40: 1 | AC40: 165062 | AD40: 316204 | AE40: 1 | AF40: 316204 | AG40: 199304.8 | AH40: 1 | AI40: 199304.8
B41: 二、其他 | H41: 0 | K41: 0 | N41: 0 | Q41: 2158278.5 | T41: 0 | W41: 0 | Z41: 0 | AC41: 0 | AF41: 0 | AI41: 0
B42: 小计 | E42: =E40+E41 -> 603000 | H42: =H40+H41 -> 1478255.8 | K42: =K40+K41 -> 0 | N42: =N40+N41 -> 0 | Q42: =Q40+Q41 -> 2158278.5 | T42: =T40+T41 -> 0 | W42: =W40+W41 -> 811226.18 | Z42: =Z40+Z41 -> 41805 | AC42: =AC40+AC41 -> 165062 | AF42: =AF40+AF41 -> 316204 | AI42: =AI40+AI41 -> 199304.8
A43: 200章矿山开拓工程 | B43: 一、爆破开采 | E43: =E44+E45 -> 8801430.8 | H43: =H44+H45 -> 16444363 | K43: =K44+K45 -> 13940765 | N43: =N44+N45 -> 16440458 | Q43: =Q44+Q45 -> 15651924 | T43: =T44+T45 -> 14899145 | W43: =W44+W45 -> 12712170 | Z43: =Z44+Z45 -> 14428454 | AC43: =AC44+AC45 -> 11423363 | AF43: =AF44+AF45 -> 13017838 | AI43: =AI44+AI45 -> 13378302
B44: 1、码头（土方、宕渣） | C44: 171048.87 | D44: 7.96 | E44: =C44*D44 -> 1361549 | F44: 594680.78 | G44: 7.96 | H44: 4733659 | I44: 374248.95 | J44: 7.96 | K44: 2979021.6 | L44: 266376.75 | M44: 7.96 | N44: 2120358.9 | O44: 313651.2 | P44: 7.96 | Q44: 2496663.5 | R44: 254457.5 | S44: 7.96 | T44: 2025481.7 | AJ44: =F44+I44+L44+O44+R44+U44+X44+AA44+AD44+AG44 -> 1803415.2
B45: 2、卸料口（骨料） | C45: 1100574.2 | D45: 6.76 | E45: =C45*D45 -> 7439881.8 | F45: 1732352.7 | G45: 6.76 | H45: 11710704 | I45: 1621559.7 | J45: 6.76 | K45: 10961743 | L45: 2118357.8 | M45: 6.76 | N45: 14320099 | O45: 1946044.5 | P45: 6.76 | Q45: 13155261 | R45: 1904388.1 | S45: 6.76 | T45: 12873664 | U45: 1880498.6 | V45: 6.76 | W45: 12712170 | X45: 2134386.7 | Y45: 6.76 | Z45: 14428454 | AA45: 1689846.6 | AB45: 6.76 | AC45: 11423363 | AD45: 1925715.6 | AE45: 6.76 | AF45: 13017838 | AG45: 1979038.7 | AH45: 6.76 | AI45: 13378302 | AJ45: =F45+I45+L45+O45+R45+U45+X45+AA45+AD45+AG45 -> 18932189
B46: 机械开采 | E46: =E47+E48 -> 0 | F46: =F47+F48 -> 0 | H46: =H47+H48 -> 0 | I46: =I47+I48 -> 0 | K46: =K47+K48 -> 0 | L46: =L47+L48 -> 6414.75 | N46: =N47+N48 -> 70177.37 | O46: =O47+O48 -> 94164.85 | Q46: =Q47+Q48 -> 1042100.8 | R46: =R47+R48 -> 116178.82 | T46: =T47+T48 -> 1285235.3 | U46: =U47+U48 -> 42304.35 | W46: =W47+W48 -> 462809.59 | X46: =X47+X48 -> 65699.5 | Z46: =Z47+Z48 -> 718752.53 | AA46: =AA47+AA48 -> 37384.2 | AC46: =AC47+AC48 -> 408983.15 | AD46: =AD47+AD48 -> 42007.51 | AF46: =AF47+AF48 -> 459562.16 | AG46: =AG47+AG48 -> 63875.4 | AI46: =AI47+AI48 -> 698796.88 | AJ46: =F46+I46+L46+O46+R46+U46+X46+AA46+AD46+AG46 -> 468029.38
B47: 1、码头（土方、宕渣） | O47: 11703.3 | P47: 11.96 | Q47: 139971.47 | R47: 13959.85 | S47: 11.96 | T47: 166959.81 | AJ47: =F47+I47+L47+O47+R47+U47+X47+AA47+AD47+AG47 -> 25663.15
B48: 2、卸料口（骨料） | L48: 6414.75 | M48: 10.940001 | N48: 70177.37 | O48: 82461.55 | P48: 10.94 | Q48: 902129.36 | R48: 102218.97 | S48: 10.94 | T48: 1118275.5 | U48: 42304.35 | V48: 10.94 | W48: 462809.59 | X48: 65699.5 | Y48: 10.94 | Z48: 718752.53 | AA48: 37384.2 | AB48: 10.94 | AC48: 408983.15 | AD48: 42007.51 | AE48: 10.94 | AF48: 459562.16 | AG48: 63875.4 | AH48: 10.94 | AI48: 698796.88 | AJ48: =F48+I48+L48+O48+R48+U48+X48+AA48+AD48+AG48 -> 442366.23
B49: 三、剥离表土运输 | C49: 135607.02 | D49: 7.71 | E49: =C49*D49 -> 1045530.1 | F49: 77168.92 | G49: 5 | H49: 385844.6 | I49: 127803.4 | J49: 5 | K49: 639017 | L49: 59744.85 | M49: 5 | N49: 298724.25 | O49: 89778.7 | P49: 5 | Q49: 448893.5 | R49: 132000.95 | S49: 5 | T49: 660004.75 | AJ49: =F49+I49+L49+O49+R49+U49+X49+AA49+AD49+AG49 -> 486496.82 | AN49: =AJ48+AJ45 -> 19374555 | AO49: =AJ48/AN49 -> 0.02283233
B50: 四、200章其他 | E50: 14547.93 | H50: 1233263.6 | K50: 24855.6 | N50: 80389.93 | Q50: 81410.13 | T50: 0 | W50: 32194.8 | Z50: 252198.14 | AC50: 116537.16 | AF50: 21553.69 | AI50: 0 | AJ50: =F50+I50+L50+O50+R50+U50+X50+AA50+AD50+AG50 -> 0
B51: 小计 | E51: =E43+E46+E49+E50 -> 9861508.9 | H51: =H43+H46+H49+H50 -> 18063472 | K51: =K43+K46+K49+K50 -> 14604638 | N51: =N43+N46+N49+N50 -> 16889749 | Q51: =Q43+Q46+Q49+Q50 -> 17224329 | T51: =T43+T46+T49+T50 -> 16844385 | W51: =W43+W46+W49+W50 -> 13207175 | Z51: =Z43+Z46+Z49+Z50 -> 15399405 | AC51: =AC43+AC46+AC49+AC50 -> 11948883 | AF51: =AF43+AF46+AF49+AF50 -> 13498954 | AI51: =AI43+AI46+AI49+AI50 -> 14077099 | AJ51: =F51+I51+L51+O51+R51+U51+X51+AA51+AD51+AG51 -> 0
...

Sheet 核心指标-开采比例
A4: 26年结算
A5: 结算项目 | C5: 单价（元/吨） | D5: 1月 | E5: 2-3月 | F5: 4-5月 | G5: 6月 | H5: 7月 | I5: 8月 | J5: 9月 | K5: 10月 | L5: 11月 | M5: 12月 | N5: 合计 | O5: 开采比例
A6: 宕渣及土方 | B6: 表土剥离 | C6: 5 | D6: ='基础资料-结算资料'!C15 -> 174272.96 | E6: ='基础资料-结算资料'!F15 -> 358266.05 | F6: ='基础资料-结算资料'!I15 -> 86628.02 | G6: ='基础资料-结算资料'!L15 -> 2276.6 | H6: ='基础资料-结算资料'!O15 -> 0 | I6: ='基础资料-结算资料'!R15 -> 5835.1 | N6: =SUM(D6:M6) -> 627278.73 | O6: =N6/N$9 -> 0.25491108
B7: 爆破开采 | C7: 7.96 | D7: ='基础资料-结算资料'!C10 -> 217005.54 | E7: ='基础资料-结算资料'!F10 -> 112348.5 | F7: ='基础资料-结算资料'!I10 -> 572343.61 | G7: ='基础资料-结算资料'!L10 -> 343040.8 | H7: ='基础资料-结算资料'!O10 -> 26172.15 | I7: ='基础资料-结算资料'!R10 -> 103959.45 | N7: =SUM(D7:M7) -> 1374870 | O7: =N7/N$9 -> 0.55871432
B8: 机械开采 | C8: 11.95 | D8: ='基础资料-结算资料'!C13 -> 224989.5 | E8: ='基础资料-结算资料'!F13 -> 41946.28 | F8: ='基础资料-结算资料'!I13 -> 177540.73 | G8: ='基础资料-结算资料'!L13 -> 6052.3 | H8: ='基础资料-结算资料'!O13 -> 5899.95 | I8: ='基础资料-结算资料'!R13 -> 2197.15 | N8: =SUM(D8:M8) -> 458625.91 | O8: =N8/N$9 -> 0.1863746
B9: 合计 | D9: =SUM(D6:D8) -> 616268 | E9: =SUM(E6:E8) -> 512560.83 | F9: =SUM(F6:F8) -> 836512.36 | G9: =SUM(G6:G8) -> 351369.7 | H9: =SUM(H6:H8) -> 32072.1 | I9: =SUM(I6:I8) -> 111991.7 | N9: =SUM(D9:M9) -> 2460774.7 | O9: /
B10: 均价 | D10: =(D6*C6+D7*C7+D8*C8)/D9 -> 8.5796332 | E10: =(E6*C6+E7*C7+E8*C8)/E9 -> 6.2175691 | F10: =(F6*C6+F7*C7+F8*C8)/F9 -> 8.5003011 | G10: =(G6*C6+G7*C7+G8*C8)/G9 -> 8.0095488 | H10: =(H6*C6+H7*C7+H8*C8)/H9 -> 8.6939962 | I10: =(I6*C6+I7*C7+I8*C8)/I9 -> 7.8840545 | N10: =(N6*C6+N7*C7+N8*C8)/N9 -> 7.9490979 | O10: /
A11: 骨料 | B11: 爆破开采 | C11: ='基础资料-结算资料'!D11 -> 6.76 | D11: ='基础资料-结算资料'!C11 -> 1815869.1 | E11: ='基础资料-结算资料'!F11 -> 1878791.6 | F11: ='基础资料-结算资料'!I11 -> 2969474.7 | G11: ='基础资料-结算资料'!L11 -> 1657446.6 | H11: ='基础资料-结算资料'!O11 -> 698341.17 | I11: ='基础资料-结算资料'!R11 -> 948122.2 | N11: =SUM(D11:M11) -> 9968045.3 | O11: =N11/N$13 -> 0.95429601
B12: 机械开采 | C12: ='基础资料-结算资料'!D14 -> 10.94 | D12: ='基础资料-结算资料'!C14 -> 42909.6 | E12: ='基础资料-结算资料'!F14 -> 38710.6 | F12: ='基础资料-结算资料'!I14 -> 132734.95 | G12: ='基础资料-结算资料'!L14 -> 126701.22 | H12: ='基础资料-结算资料'!O14 -> 62937 | I12: ='基础资料-结算资料'!R14 -> 73405.05 | N12: =SUM(D12:M12) -> 477398.42 | O12: =N12/N$13 -> 0.045703986
B13: 合计 | D13: =SUM(D11:D12) -> 1858778.7 | E13: =SUM(E11:E12) -> 1917502.2 | F13: =SUM(F11:F12) -> 3102209.6 | G13: =SUM(G11:G12) -> 1784147.8 | H13: =SUM(H11:H12) -> 761278.17 | I13: =SUM(I11:I12) -> 1021527.2 | N13: =SUM(D13:M13) -> 10445444
B14: 均价 | D14: =(D11*C11+C12*D12)/D13 -> 6.8564946 | E14: =(E11*C11+E12*C12)/E13 -> 6.844386 | F14: =(F11*C11+F12*C12)/F13 -> 6.9388506 | G14: =(G11*C11+G12*C12)/G13 -> 7.0568426 | H14: =(H11*C11+H12*C12)/H13 -> 7.1055723 | I14: =(I11*C11+I12*C12)/I13 -> 7.060367 | N14: =(N11*C11+N12*C12)/N13 -> 6.9510427
A17: 25年结算
A18: 结算项目 | C18: 单价（元/吨） | D18: 1月 | E18: 2-3月 | F18: 4-5月 | G18: 6月 | H18: 7月 | I18: 8月 | J18: 9月 | K18: 10月 | L18: 11月 | M18: 12月 | N18: 合计 | O18: 开采比例
A19: 宕渣及土方 | B19: 表土剥离 | C19: 5 | D19: ='基础资料-结算资料'!C49 -> 135607.02 | E19: ='基础资料-结算资料'!F49 -> 77168.92 | F19: ='基础资料-结算资料'!I49+'基础资料-结算资料'!L49 -> 187548.25 | G19: ='基础资料-结算资料'!O49 -> 89778.7 | H19: ='基础资料-结算资料'!R49 -> 132000.95 | I19: ='基础资料-结算资料'!U49 -> 0 | J19: ='基础资料-结算资料'!X49 -> 0 | K19: ='基础资料-结算资料'!AA49 -> 0 | L19: ='基础资料-结算资料'!AD49 -> 0 | M19: ='基础资料-结算资料'!AG49 -> 0 | N19: =SUM(D19:M19) -> 622103.84 | O19: =N19/N$22 -> 0.23724219
B20: 爆破开采 | C20: 7.96 | D20: ='基础资料-结算资料'!C44 -> 171048.87 | E20: ='基础资料-结算资料'!F44 -> 594680.78 | F20: ='基础资料-结算资料'!I44+'基础资料-结算资料'!L44 -> 640625.7 | G20: ='基础资料-结算资料'!O44 -> 313651.2 | H20: ='基础资料-结算资料'!R44 -> 254457.5 | I20: ='基础资料-结算资料'!U44 -> 0 | J20: ='基础资料-结算资料'!X44 -> 0 | K20: ='基础资料-结算资料'!AA44 -> 0 | L20: ='基础资料-结算资料'!AD44 -> 0 | M20: ='基础资料-结算资料'!AG44 -> 0 | N20: =SUM(D20:M20) -> 1974464.1 | O20: =N20/N$22 -> 0.75297105
B21: 机械开采 | C21: 11.95 | D21: ='基础资料-结算资料'!C47 -> 0 | E21: ='基础资料-结算资料'!F47 -> 0 | F21: ='基础资料-结算资料'!I47+'基础资料-结算资料'!L47 -> 0 | G21: ='基础资料-结算资料'!O47 -> 11703.3 | H21: ='基础资料-结算资料'!R47 -> 13959.85 | I21: ='基础资料-结算资料'!U47 -> 0 | J21: ='基础资料-结算资料'!X47 -> 0 | K21: ='基础资料-结算资料'!AA47 -> 0 | L21: ='基础资料-结算资料'!AD47 -> 0 | M21: ='基础资料-结算资料'!AG47 -> 0 | N21: =SUM(D21:M21) -> 25663.15 | O21: =N21/N$22 -> 0.0097867616
B22: 合计 | D22: =SUM(D19:D21) -> 306655.89 | E22: =SUM(E19:E21) -> 671849.7 | F22: =SUM(F19:F21) -> 828173.95 | G22: =SUM(G19:G21) -> 415133.2 | H22: =SUM(H19:H21) -> 400418.3 | I22: =SUM(I19:I21) -> 0 | J22: =SUM(J19:J21) -> 0 | K22: =SUM(K19:K21) -> 0 | ... M22: =SUM(M19:M21) -> 0 | N22: =SUM(D22:M22) -> 2622231 | O22: /
B23: 均价 | D23: =(D19*7.71+D20*C20+D21*C21)/D22 -> 7.8494469 | E23: =(E19*C19+E20*C20+E21*C21)/E22 -> 7.6200132 | F23: =(F19*C19+F20*C20+F21*C21)/F22 -> 7.2896785 | G23: =(G19*C19+G20*C20+G21*C21)/G22 -> 7.432341 | H23: =(H19*C19+H20*C20+H21*C21)/H22 -> 7.1233174 | I23: =(I19*C19+I20*C20+I21*C21)/I22 -> #DIV/0! | J23: =(J19*C19+J20*C20+J21*C21)/J22 -> #DIV/0! | K23: =(K19*C19+K20*C20+K21*C21)/K22 -> #DIV/0! | L23: =(L19*C19+L20*C20+L21*C21)/L22 -> #DIV/0! | M23: =(M19*C19+M20*C20+M21*C21)/M22 -> #DIV/0! | N23: =(N19*C19+N20*C20+N21*C21)/N22 -> 7.2968123 | O23: /
A24: 骨料 | B24: 爆破开采 | C24: 6.76 | D24: ='基础资料-结算资料'!C45 -> 1100574.2 | E24: ='基础资料-结算资料'!F45 -> 1732352.7 | F24: ='基础资料-结算资料'!I45+'基础资料-结算资料'!L45 -> 3739917.4 | G24: ='基础资料-结算资料'!O45 -> 1946044.5 | H24: ='基础资料-结算资料'!R45 -> 1904388.1 | I24: ='基础资料-结算资料'!U45 -> 1880498.6 | J24: ='基础资料-结算资料'!X45 -> 2134386.7 | K24: ='基础资料-结算资料'!AA45 -> 1689846.6 | L24: ='基础资料-结算资料'!AD45 -> 1925715.6 | M24: ='基础资料-结算资料'!AG45 -> 1979038.7 | N24: =SUM(D24:M24) -> 20032763 | O24: =N24/N$26 -> 0.97839495
B25: 机械开采 | C25: 10.94 | D25: ='基础资料-结算资料'!C48 -> 0 | E25: ='基础资料-结算资料'!F48 -> 0 | F25: ='基础资料-结算资料'!I48+'基础资料-结算资料'!L48 -> 6414.75 | G25: ='基础资料-结算资料'!O48 -> 82461.55 | H25: ='基础资料-结算资料'!R48 -> 102218.97 | I25: ='基础资料-结算资料'!U48 -> 42304.35 | J25: ='基础资料-结算资料'!X48 -> 65699.5 | K25: ='基础资料-结算资料'!AA48 -> 37384.2 | L25: ='基础资料-结算资料'!AD48 -> 42007.51 | M25: ='基础资料-结算资料'!AG48 -> 63875.4 | N25: =SUM(D25:M25) -> 442366.23 | O25: =N25/N$26 -> 0.021605052
B26: 合计 | D26: =SUM(D24:D25) -> 1100574.2 | E26: =SUM(E24:E25) -> 1732352.7 | F26: =SUM(F24:F25) -> 3746332.2 | G26: =SUM(G24:G25) -> 2028506 | H26: =SUM(H24:H25) -> 2006607.1 | I26: =SUM(I24:I25) -> 1922802.9 | J26: =SUM(J24:J25) -> 2200086.2 | K26: =SUM(K24:K25) -> 1727230.8 | ... M26: =SUM(M24:M25) -> 2042914.1 | N26: =SUM(D26:M26) -> 20475129 | O26: /
B27: 均价 | D27: =(D24*C24+D25*C25)/D26 -> 6.76 | E27: =(E24*C24+E25*C25)/E26 -> 6.76 | F27: =(F24*C24+F25*C25)/F26 -> 6.7671573 | G27: =(G24*C24+G25*C25)/G26 -> 6.9299227 | H27: =(H24*C24+H25*C25)/H26 -> 6.9729342 | I27: =(I24*C24+I25*C25)/I26 -> 6.8519658 | J27: =(J24*C24+J25*C25)/J26 -> 6.8848242 | K27: =(K24*C24+K25*C25)/K26 -> 6.850472 | L27: =(L24*C24+L25*C25)/L26 -> 6.8492358 | M27: =(M24*C24+M25*C25)/M26 -> 6.8906953 | N27: =(N24*C24+N25*C25)/N26 -> 6.8503091 | O27: /
E30: 差异 | F30: 影响金额 | J30: 差异 | K30: 影响金额 | L30: 备注（为一月差异）
C31: 25年开采宕渣 | D31: ='基础资料-生产资料'!Q16+'基础资料-生产资料'!Q17 -> 2611128.5 | E31: =D32-D31 -> 11102.5 | F31: =E31*N23 -> 81012.858 | H31: 25年开采骨料 | I31: ='基础资料-生产资料'!Q18+'基础资料-生产资料'!Q19 -> 20165398 | J31: =I32-I31 -> 309731.81 | K31: =J31*C24 -> 2093787
C32: 25年结算宕渣 | D32: =N22 -> 2622231 | H32: 25年结算骨料 | I32: =N24+N25 -> 20475129
C34: 26年开采宕渣 | D34: ='基础资料-生产资料'!Q6+'基础资料-生产资料'!Q7 -> 2418165.7 | E34: =D35-D34 -> 42609 | F34: =E34*N10 -> 338703.11 | H34: 26年开采骨料 | I34: ='基础资料-生产资料'!Q8+'基础资料-生产资料'!Q9 -> 10445444
C35: 26年结算宕渣 | D35: =N9 -> 2460774.7 | H35: 26年结算骨料 | I35: =N13 -> 10445444
E38: =E31+E34 -> 53711.5
E39: 53260.8
E40: =E38-E39 -> 450.7

Sheet 1
A2: 2026年度生产数据（调整版）
O4: 单位：吨
A5: 项目 | E5: 1月 | F5: 2月 | G5: 3月 | H5: 4月 | I5: 5月 | J5: 6月 | K5: 7月 | L5: 8月 | M5: 9月 | N5: 10月 | O5: 11月 | P5: 12月 | Q5: 合计
A6: 开采量 | B6: 大皇山 | C6: 宕渣 | E6: 189082.9 | F6: 32925.05 | G6: 79963.73 | H6: 90578.25 | I6: 68277.5 | J6: 308815.3 | K6: 32072.1 | L6: 111991.7 | Q6: =SUM(E6:P6) -> 913706.53
C7: 土方 | E7: 427130.5 | F7: 122428.3 | G7: 277243.75 | H7: 420235.96 | I7: 257420.65 | J7: 0 | K7: 0 | L7: 0 | Q7: =SUM(E7:P7) -> 1504459.2
C8: 老线 | D8: 破碎量： | E8: 1332094.2 | F8: 669731.4 | G8: 724342.1 | H8: 1274223.2 | I8: 973700.5 | J8: 1185003.6 | K8: 597014.55 | L8: 1021527.2 | Q8: =SUM(E8:P8) -> 7777636.9
C9: 新线 | D9: 破碎量： | E9: 526684.49 | F9: 241147.94 | G9: 282280.77 | H9: 480767.83 | I9: 373518.09 | J9: 599144.12 | K9: 164263.62 | L9: 0 | Q9: =SUM(E9:P9) -> 2667806.9
A12: 2025年度生产数据（调整版）
O14: 单位：吨
A15: 项目 | E15: 1月 | F15: 2月 | G15: 3月 | H15: 4月 | I15: 5月 | J15: 6月 | K15: 7月 | L15: 8月 | M15: 9月 | N15: 10月 | O15: 11月 | P15: 12月 | Q15: 合计
A16: 开采量 | B16: 大皇山 | C16: 宕渣 | E16: 0 | F16: 0 | G16: 0 | H16: 0 | I16: 0 | J16: 19808.4 | K16: 0 | L16: 0 | M16: 0 | N16: 0 | O16: 0 | P16: 0 | Q16: =SUM(E16:P16) -> 19808.4
C17: 土方 | E17: 302452.34 | F17: 268007.6 | G17: 394472.15 | H17: 494860.65 | I17: 303153.05 | J17: 385535.1 | K17: 400373.65 | L17: 42465.6 | M17: 0 | N17: 0 | O17: 0 | P17: 0 | Q17: =SUM(E17:P17) -> 2591320.1
C18: 老线 | D18: 破碎量： | E18: 620265.55 | F18: 451278.7 | G18: 814257.5 | H18: 1120405 | I18: 1461011.8 | J18: 1447575.1 | K18: 1432463.2 | L18: 1314101.5 | M18: 1452347.9 | N18: 1206269.9 | O18: 1326113.1 | P18: 1435938.1 | Q18: =SUM(E18:P18) -> 14082027
C19: 新线 | D19: 破碎量： | E19: 169547.98 | F19: 146213.5 | G19: 320603.03 | H19: 501154.67 | I19: 667030.08 | J19: 618556.08 | K19: 594737.02 | L19: 608701.43 | M19: 686250.66 | N19: 520960.97 | O19: 641610 | P19: 606976.01 | Q19: =SUM(E19:P19) -> 6082341.4
